examples/orderbook/OpenExecuteCloseOrderbook.json
[
  {
    "id": "XMHD3SULE6IEVE7M7F6LFP42KTUSHJNXAW5SSUHCUYNBSGL677HA",
    "application-transaction": {
      "approval-program": "\n \u0005\u0001\u0000\u0004\u0006��\u0006&\u0003\u0004\u0015\u001f|u\b\u0000\u0000\u0000\u0000\u0000\u0000\u0000\u0000\b\u0000\u0000\u0000\u0000\u0000\u0000\u0000\u00011\u0018\u0014%\u000b1\u0019\b�\f\u0005\u0012\u0000\u0000\u0000\u0000\u0000\u0000\u0000\u0000\u0000\u0000\u0005\u0004\u0000\u0000\u0000\u0000\u0000\u0000\u0000\u0000\u0000\u0000\u00006\u001a\u0001\u0017�01\u0016\"\tI8\u0010\"\u0012D�\u0000\u0002\"C�\u0002\u0000��8\u00072\n\u0012D��8\b!\u0004\u0012D�$�\u0010���\u0011#�\u00122\n�\u00002\n�\u0014#�\u0001��(6\u001a\u0003\u00176\u001a\u0002\u00176\u001a\u0001\u0017�01\u0016\"\tI8\u0010$\u0012D1\u0016�\u0002\tI8\u0010\"\u0012D1\u0016�\u0003\tI8\u0010\"\u0012D�\u0000\u0005\u0016P�\"C�\u0006\u0001�\u0000I��8\u0000��8\u0000\u0012IA\u0000\n��8\u0000��8\u0000\u0012\u0010�\u0000�\u0000D��8\u00072\n\u0012D��8\b���\u0018\u0012D��8\u00072\n\u0012D��8\b���\f\u0012D2\n��8\u0011p\u0000LHD��8\u00142\n\u0012D�%�\u0010�\u0004��F\u0006�\u001a�\u0001\n�\u001f��\u0006\n \u0004\u0000\u0001\u0004\u0006&\u0007\u0005owner\tsellAsset\bbuyAsset\tsellQuant\bbuyQuant\u0004\u0015\u001f|u\u00001\u0018\u0014%\u000b1\u0019\b�\f\u0002\u0000\u0000\u0000\u0000\u0000\u0000\u0000\u0000\u0002�\u0002q\u0000\u0000\u0000\u0000\u0000\u0000\u0000\u0000\u0000\u0000\u0000�\u0001\u0001��+d\u001d\"'\u0004d\u001fHHL\u0014D��\u0003\u00002\n��p\u0000LHA\u0000!2\n��p\u0000H\"\u0012D�$�\u0010���\u0011���\u0014���\u0015\"�\u0012\"�\u0001������\u0001��'\u00056\u001a\u0005\u0017�\u001c6\u001a\u0004\u00176\u001a\u0003\u00176\u001a\u0002\u0017�06\u001a\u0001\u0017�0�\u0000\u0004P�#C�\u0005\u0001)��g*��g+��g'\u0004��g(��g2\n�6\u001a\u0001\u0017�01\u0016#\tI8\u0010#\u0012D�\u0000\u0002#C�\u0002\u0000'\u0006)d��\u0012I@\u0000\u0006*d��\u0012\u0011�\u0000��8\u00072\n\u0012D��8\b���\u0006\u000fD�\u0000D�$�\u0010���\u0011\"�\u00122\n�\u00002\n�\u0014\"�\u0001��'\u00056\u001a\u0003\u0017�\u001c6\u001a\u0002\u0017�06\u001a\u0001\u0017�01\u0016#\tI8\u0010$\u0012D1\u0016�\u0002\tI8\u0010%\u0012D�\u0000\u000fI\u0015� \n\u0016W\u0006\u0002LPP�#C�\u0005\u0001'\u0006��8\u0018r\bH62\u0000r\u0007H\u0012D��8\u0011*d\u0012D��8\u0011��\u0012D)d��\u0012D(d��\u0012D��8\u0000��p\u0000LHD��8\u0012����\u00002\n)dp\u0000H�\u0000\u000fD(d*dp\u0000LHD�$�\u0010��8\u0011�\u0011��8\u0012�\u0012(d�\u0014\"�\u0001��$�\u0010���\u0011�\u0000�\u0012��8\u0000�\u0014\"�\u0001�2\n)dp\u0000H\"\u0012A\u0000\u000b��8\u0000������[��8\u0018r\bH62\u0000r\u0007HP2\nP�\u0000�6\u001a\u0002\u0017�06\u001a\u0001\u0017�0�\u0000\u0002#C�\u0002\u00001\u0000(d\u0012A\u0000L�$�\u0010���\u00111\u0000�\u00141\u0000�\u0015\"�\u0012\"�\u0001�2\n��p\u0000LHA\u0000\u0017�$�\u0010���\u0011(d�\u0014(d�\u0015\"�\u0012\"�\u0001��#�\u0010(d�\u0007(d�\t\"�\u0001�B\u0000;2\n��p\u0000LH\u0014D2\n��p\u0000H\"\u0012D�$�\u0010���\u0011(d�\u0014(d�\u0015\"�\u0012\"�\u0001��#�\u0010(d�\u0007(d�\t\"�\u0001���\u0004��F\u00066\u001a\u0000�\u0001��\u0000�\u0004i6�\u0010�\u0004U���6\u001a\u0000�\u0002���M\u0000�\u0004�\u000e%R6\u001a\u0000�\u0001�+\u0000�\u001e��8\u0011�0)�\u001a���0*�\u001a��\u0016�\u001a��\u0016�\u001a��8\u0000�\u001c*�\u001a\"�5$�4#�7#�6#�\u0001��;\"\t�:W\u0004\u0000�=�\u0001�\"�\u0010��8\b�\b�\u0001r\bH�\u0007#�\u0001�%�\u0010�\u0004i6�\u0010�\u001a�\u0001�\u0018��8\u0011�0)�\u001a#�\u0001��$�\u0010��8\u0011�\u0011�\u0001r\bH�\u0014��8\u0012�\u0012#�\u0001��$�\u0010��8\u0011�\u0011��8\u0000�\u0014��8\u0000�\u0015#�\u0012#�\u0001�2\n��8\u0011p\u0000LH\u0014D�\"�\u0010��8\u0000�\u0007!\u0004�\b#�\u0001��\u0001�\u0000F\u0001�(6\u001a\u0003\u0017�06\u001a\u0002\u0017�06\u001a\u0001\u0017�2�\u0000\u000fI\u0015� \n\u0016W\u0006\u0002LPP�\"C�\u0003\u0001��r\u0007H2\n\u0012D��r\bH��p\u0000H#\rD��r\bH��r\u0007HP2\nP�\"C�\u0004�D{66\u001a\u0000�\u0001��\u0000�\u0004�l3\u0005�\u0004b<k�\u0004\u0015�R6\u001a\u0000�\u0003���\u0012��\u0000",
      "clear-state-program": "\n",
      "on-completion": "update",
      "application-args": [
        "uER7Ng=="
      ]
    },
    "first-valid": 19,
    "last-valid": 1019,
    "tx-type": "appl",
    "fee": 1000,
    "sender": "LRYB3UXSHBHBA65RG6OENJ53XWXW6EJ24ZADDQMJZCMXNXATOMBJAB2FPY",
    "confirmed-round": 20,
    "round-time": 1707917359,
    "intra-round-offset": 0,
    "genesis-hash": "3U09rxb6HtYmLEjXZfBtnSK6fwso1lUIrwRpAbIBanM=",
    "genesis-id": "dockernet-v1",
    "note": "",
    "lease": "",
    "created-application-index": 1150,
    "signature": {
      "sig": "o2X6j2YmqrB1WnAHgG8lEid7+2bVc+XCmLOn/+p4VmpqafMWPCYQCG1TBUiN3jMSwZeFt9klNCS3ESKrSg14Dw=="
    }
  },
  {
    "id": "36OP2YUZ3SGUOED2MB3HAYAG4DFWZ7PEVJSCPHQXD22C2R3MP2WA",
    "application-transaction": {
      "application-id": 1150,
      "approval-program": "",
      "clear-state-program": "",
      "on-completion": "update",
      "application-args": [
        "xGwzBQ==",
        "AA=="
      ],
      "foreign-assets": [
        1151
      ]
    },
    "first-valid": 28,
    "last-valid": 1028,
    "tx-type": "appl",
    "fee": 3000,
    "sender": "XI5PSOZULJ4POLJRZHUPYXUYXU6RG5HJC33VGNTBJAFHPZ6HAKW246GMUY",
    "confirmed-round": 29,
    "round-time": 1707917584,
    "intra-round-offset": 1,
    "genesis-hash": "3U09rxb6HtYmLEjXZfBtnSK6fwso1lUIrwRpAbIBanM=",
    "genesis-id": "dockernet-v1",
    "group": "ekVuGt0JYF2z50sB25/wkXvYjYVKyc6F9zebNUvhvQk=",
    "note": "",
    "lease": "",
    "inner-txns": [
      {
        "id": "FADMB5A2LVAPNFHLMYSAAGRTPURYFZUKIYHMSEL66CJF3YLLVHNQ",
        "asset-transfer-transaction": {
          "asset-id": 1151,
          "amount": null,
          "receiver": "7IQBTRVFFPIXZ43YG2DP4XRAO7KF7QGPUX5Z2DHFRKGKTFJ2LS3JA6ZB6Q",
          "sender": "7IQBTRVFFPIXZ43YG2DP4XRAO7KF7QGPUX5Z2DHFRKGKTFJ2LS3JA6ZB6Q"
        },
        "first-valid": 28,
        "last-valid": 1028,
        "tx-type": "axfer",
        "fee": 0,
        "sender": "7IQBTRVFFPIXZ43YG2DP4XRAO7KF7QGPUX5Z2DHFRKGKTFJ2LS3JA6ZB6Q",
        "confirmed-round": 29,
        "round-time": 1707917584,
        "intra-round-offset": 2,
        "genesis-hash": "3U09rxb6HtYmLEjXZfBtnSK6fwso1lUIrwRpAbIBanM=",
        "genesis-id": "dockernet-v1",
        "note": "",
        "lease": ""
      }
    ],
    "signature": {
      "sig": "UHFH2OueBSpDy6X5XNBjHMb5yO8AwJ8OYDuKYGF9Syxi2qvKtUaOJvj/chKGMMnZiXYiaPqP0+9E6Oc0ruOzAw=="
    }
  },
  {
    "id": "PCIKDBKVY3QUXNZ3UTZVBKXFGUV2UC4IKI6D6PG54T2MYRSJ4ONA",
    "application-transaction": {
      "application-id": 1150,
      "approval-program": "",
      "clear-state-program": "",
      "on-completion": "update",
      "application-args": [
        "Yjxr6w==",
        "AA==",
        "AAAAAAAAAAo=",
        "AAAAAAAAABQ="
      ],
      "foreign-assets": [
        1154
      ]
    },
    "first-valid": 28,
    "last-valid": 1028,
    "tx-type": "appl",
    "fee": 8000,
    "sender": "XI5PSOZULJ4POLJRZHUPYXUYXU6RG5HJC33VGNTBJAFHPZ6HAKW246GMUY",
    "confirmed-round": 29,
    "round-time": 1707917584,
    "intra-round-offset": 6,
    "genesis-hash": "3U09rxb6HtYmLEjXZfBtnSK6fwso1lUIrwRpAbIBanM=",
    "genesis-id": "dockernet-v1",
    "group": "ekVuGt0JYF2z50sB25/wkXvYjYVKyc6F9zebNUvhvQk=",
    "note": "",
    "lease": "",
    "inner-txns": [
      {
        "id": "O5KYEEOC4H3WSJGWLCPCIRJHMJI3CGWXO5AAOOYIZY4HYR6WZJBQ",
        "application-transaction": {
          "approval-program": "\n \u0004\u0000\u0001\u0004\u0006&\u0007\u0005owner\tsellAsset\bbuyAsset\tsellQuant\bbuyQuant\u0004\u0015\u001f|u\u00001\u0018\u0014%\u000b1\u0019\b�\f\u0002\u0000\u0000\u0000\u0000\u0000\u0000\u0000\u0000\u0002�\u0002q\u0000\u0000\u0000\u0000\u0000\u0000\u0000\u0000\u0000\u0000\u0000�\u0001\u0001��+d\u001d\"'\u0004d\u001fHHL\u0014D��\u0003\u00002\n��p\u0000LHA\u0000!2\n��p\u0000H\"\u0012D�$�\u0010���\u0011���\u0014���\u0015\"�\u0012\"�\u0001������\u0001��'\u00056\u001a\u0005\u0017�\u001c6\u001a\u0004\u00176\u001a\u0003\u00176\u001a\u0002\u0017�06\u001a\u0001\u0017�0�\u0000\u0004P�#C�\u0005\u0001)��g*��g+��g'\u0004��g(��g2\n�6\u001a\u0001\u0017�01\u0016#\tI8\u0010#\u0012D�\u0000\u0002#C�\u0002\u0000'\u0006)d��\u0012I@\u0000\u0006*d��\u0012\u0011�\u0000��8\u00072\n\u0012D��8\b���\u0006\u000fD�\u0000D�$�\u0010���\u0011\"�\u00122\n�\u00002\n�\u0014\"�\u0001��'\u00056\u001a\u0003\u0017�\u001c6\u001a\u0002\u0017�06\u001a\u0001\u0017�01\u0016#\tI8\u0010$\u0012D1\u0016�\u0002\tI8\u0010%\u0012D�\u0000\u000fI\u0015� \n\u0016W\u0006\u0002LPP�#C�\u0005\u0001'\u0006��8\u0018r\bH62\u0000r\u0007H\u0012D��8\u0011*d\u0012D��8\u0011��\u0012D)d��\u0012D(d��\u0012D��8\u0000��p\u0000LHD��8\u0012����\u00002\n)dp\u0000H�\u0000\u000fD(d*dp\u0000LHD�$�\u0010��8\u0011�\u0011��8\u0012�\u0012(d�\u0014\"�\u0001��$�\u0010���\u0011�\u0000�\u0012��8\u0000�\u0014\"�\u0001�2\n)dp\u0000H\"\u0012A\u0000\u000b��8\u0000������[��8\u0018r\bH62\u0000r\u0007HP2\nP�\u0000�6\u001a\u0002\u0017�06\u001a\u0001\u0017�0�\u0000\u0002#C�\u0002\u00001\u0000(d\u0012A\u0000L�$�\u0010���\u00111\u0000�\u00141\u0000�\u0015\"�\u0012\"�\u0001�2\n��p\u0000LHA\u0000\u0017�$�\u0010���\u0011(d�\u0014(d�\u0015\"�\u0012\"�\u0001��#�\u0010(d�\u0007(d�\t\"�\u0001�B\u0000;2\n��p\u0000LH\u0014D2\n��p\u0000H\"\u0012D�$�\u0010���\u0011(d�\u0014(d�\u0015\"�\u0012\"�\u0001��#�\u0010(d�\u0007(d�\t\"�\u0001���\u0004��F\u00066\u001a\u0000�\u0001��\u0000�\u0004i6�\u0010�\u0004U���6\u001a\u0000�\u0002���M\u0000�\u0004�\u000e%R6\u001a\u0000�\u0001�+\u0000",
